---------------------------------------------------------------------------
ValueError                                Traceback (most recent call last)
Cell In[4], line 52
     49     return bot
     51 if __name__ == "__main__":
---> 52     bot = main()

Cell In[4], line 46, in main()
     43     print(f"Runtime: {result['runtime_seconds']}s")
     45 # Export results
---> 46 excel_file = bot.export_to_excel()
     47 print(f"\nResults exported to: {excel_file}")
     49 return bot

Cell In[3], line 437, in TextToSQLBot.export_to_excel(self, filename)
    434     filename = f"text_to_sql_results_{timestamp}.xlsx"
    436 df = pd.DataFrame(self.results)
--> 437 df.columns = ['User Query', 'Relevant Tables', 'SQL Query Generated', 'Agent Answer', 'Runtime (seconds)']
    439 # Save to Excel
    440 filepath = Path(filename)

File /anaconda/envs/azureml_py38/lib/python3.10/site-packages/pandas/core/generic.py:6313, in NDFrame.__setattr__(self, name, value)
   6311 try:
   6312     object.__getattribute__(self, name)
-> 6313     return object.__setattr__(self, name, value)
   6314 except AttributeError:
   6315     pass

File properties.pyx:69, in pandas._libs.properties.AxisProperty.__set__()

File /anaconda/envs/azureml_py38/lib/python3.10/site-packages/pandas/core/generic.py:814, in NDFrame._set_axis(self, axis, labels)
    809 """
    810 This is called from the cython code when we set the `index` attribute
    811 directly, e.g. `series.index = [1, 2, 3]`.
    812 """
    813 labels = ensure_index(labels)
--> 814 self._mgr.set_axis(axis, labels)
    815 self._clear_item_cache()

File /anaconda/envs/azureml_py38/lib/python3.10/site-packages/pandas/core/internals/managers.py:238, in BaseBlockManager.set_axis(self, axis, new_labels)
    236 def set_axis(self, axis: AxisInt, new_labels: Index) -> None:
    237     # Caller is responsible for ensuring we have an Index object.
--> 238     self._validate_set_axis(axis, new_labels)
    239     self.axes[axis] = new_labels

File /anaconda/envs/azureml_py38/lib/python3.10/site-packages/pandas/core/internals/base.py:98, in DataManager._validate_set_axis(self, axis, new_labels)
     95     pass
     97 elif new_len != old_len:
---> 98     raise ValueError(
     99         f"Length mismatch: Expected axis has {old_len} elements, new "
    100         f"values have {new_len} elements"
    101     )

ValueError: Length mismatch: Expected axis has 6 elements, new values have 5 elements
